Workbook

Sheet Master Sheet-UK
A1: Sr no | B1: Pant Name | C1: Waist | D1: Total Stock | E1: Starting Stock | F1: Shipment 2 | G1: Shipment 3 | H1: Shipment 4 | I1: Sold (auto) | J1: Current Stock
A2: 1 | B2: 501 Light Blue | C2: 32 | D2: =(E2+F2+G2) -> 35 | E2: 2 | G2: 33 | I2: =SUMIFS('Master UK Sales'!D:D, 'Master UK Sales'!B:B, B2, 'Master UK Sales'!C:C, C2) -> 2 | J2: =D2-I2 -> 33
A3: 2 | B3: 501 Light Blue | C3: 34 | D3: =(E3+F3+G3) -> 38 | E3: 5 | G3: 33 | I3: =SUMIFS('Master UK Sales'!D:D, 'Master UK Sales'!B:B, B3, 'Master UK Sales'!C:C, C3) -> 8 | J3: =D3-I3 -> 30
A4: 3 | B4: 501 Light Blue | C4: 36 | D4: =(E4+F4+G4) -> 22 | E4: 2 | G4: 20 | I4: =SUMIFS('Master UK Sales'!D:D, 'Master UK Sales'!B:B, B4, 'Master UK Sales'!C:C, C4) -> 4 | J4: =D4-I4 -> 18
A5: 4 | B5: 501 Mid Blue | C5: 32 | D5: =(E5+F5+G5) -> 12 | E5: 3 | F5: 9 | I5: =SUMIFS('Master UK Sales'!D:D, 'Master UK Sales'!B:B, B5, 'Master UK Sales'!C:C, C5) -> 11 | J5: =D5-I5 -> 1
A6: 5 | B6: 501 Mid Blue | C6: 34 | D6: =(E6+F6+G6) -> 14 | E6: 4 | F6: 10 | I6: =SUMIFS('Master UK Sales'!D:D, 'Master UK Sales'!B:B, B6, 'Master UK Sales'!C:C, C6) -> 14 | J6: =D6-I6 -> 0
A7: 6 | B7: 501 Mid Blue | C7: 36 | D7: =(E7+F7+G7) -> 11 | E7: 2 | F7: 9 | I7: =SUMIFS('Master UK Sales'!D:D, 'Master UK Sales'!B:B, B7, 'Master UK Sales'!C:C, C7) -> 9 | J7: =D7-I7 -> 2
A8: 7 | B8: 501 Navy Blue | C8: 32 | D8: =(E8+F8+G8) -> 26 | E8: 6 | G8: 20 | I8: =SUMIFS('Master UK Sales'!D:D, 'Master UK Sales'!B:B, B8, 'Master UK Sales'!C:C, C8) -> 6 | J8: =D8-I8 -> 20
A9: 7 | B9: 501 Navy Blue | C9: 34 | D9: =(E9+F9+G9) -> 28 | E9: 5 | G9: 23 | I9: =SUMIFS('Master UK Sales'!D:D, 'Master UK Sales'!B:B, B9, 'Master UK Sales'!C:C, C9) -> 6 | J9: =D9-I9 -> 22
A10: 7 | B10: 501 Navy Blue | C10: 36 | D10: =(E10+F10+G10) -> 12 | E10: 2 | G10: 10 | I10: =SUMIFS('Master UK Sales'!D:D, 'Master UK Sales'!B:B, B10, 'Master UK Sales'!C:C, C10) -> 2 | J10: =D10-I10 -> 10
A11: 7 | B11: 501 Black | C11: 32 | D11: =(E11+F11+G11) -> 26 | E11: 1 | F11: 16 | G11: 9 | I11: =SUMIFS('Master UK Sales'!D:D, 'Master UK Sales'!B:B, B11, 'Master UK Sales'!C:C, C11) -> 7 | J11: =D11-I11 -> 19
A12: 7 | B12: 501 Black | C12: 34 | D12: =(E12+F12+G12) -> 17 | E12: 2 | F12: 15 | I12: =SUMIFS('Master UK Sales'!D:D, 'Master UK Sales'!B:B, B12, 'Master UK Sales'!C:C, C12) -> 15 | J12: =D12-I12 -> 2
A13: 7 | B13: 501 Black | C13: 36 | D13: =(E13+F13+G13) -> 13 | E13: 1 | F13: 12 | I13: =SUMIFS('Master UK Sales'!D:D, 'Master UK Sales'!B:B, B13, 'Master UK Sales'!C:C, C13) -> 9 | J13: =D13-I13 -> 4
A14: 7 | B14: 511 Light Blue | C14: 32 | D14: =(E14+F14+G14) -> 3 | E14: 3 | I14: =SUMIFS('Master UK Sales'!D:D, 'Master UK Sales'!B:B, B14, 'Master UK Sales'!C:C, C14) -> 3 | J14: =D14-I14 -> 0
A15: 7 | B15: 511 Light Blue | C15: 34 | D15: =(E15+F15+G15) -> 4 | E15: 4 | I15: =SUMIFS('Master UK Sales'!D:D, 'Master UK Sales'!B:B, B15, 'Master UK Sales'!C:C, C15) -> 4 | J15: =D15-I15 -> 0
A16: 7 | B16: 511 Light Blue | C16: 36 | D16: =(E16+F16+G16) -> 3 | E16: 3 | I16: =SUMIFS('Master UK Sales'!D:D, 'Master UK Sales'!B:B, B16, 'Master UK Sales'!C:C, C16) -> 3 | J16: =D16-I16 -> 0
B17: 511 Mid Blue | C17: 32 | D17: =(E17+F17+G17) -> 0 | I17: =SUMIFS('Master UK Sales'!D:D, 'Master UK Sales'!B:B, B17, 'Master UK Sales'!C:C, C17) -> 0 | J17: =D17-I17 -> 0
B18: 511 Mid Blue | C18: 34 | D18: =(E18+F18+G18) -> 4 | G18: 4 | I18: =SUMIFS('Master UK Sales'!D:D, 'Master UK Sales'!B:B, B18, 'Master UK Sales'!C:C, C18) -> 0 | J18: =D18-I18 -> 4
B19: 511 Mid Blue | C19: 36 | D19: =(E19+F19+G19) -> 0 | I19: =SUMIFS('Master UK Sales'!D:D, 'Master UK Sales'!B:B, B19, 'Master UK Sales'!C:C, C19) -> 0 | J19: =D19-I19 -> 0
A20: 7 | B20: 511 Navy Blue | C20: 32 | D20: =(E20+F20+G20) -> 10 | E20: 4 | G20: 6 | I20: =SUMIFS('Master UK Sales'!D:D, 'Master UK Sales'!B:B, B20, 'Master UK Sales'!C:C, C20) -> 6 | J20: =D20-I20 -> 4
A21: 7 | B21: 511 Navy Blue | C21: 34 | D21: =(E21+F21+G21) -> 17 | E21: 5 | G21: 12 | I21: =SUMIFS('Master UK Sales'!D:D, 'Master UK Sales'!B:B, B21, 'Master UK Sales'!C:C, C21) -> 7 | J21: =D21-I21 -> 10
A22: 7 | B22: 511 Navy Blue | C22: 36 | D22: =(E22+F22+G22) -> 13 | E22: 5 | G22: 8 | I22: =SUMIFS('Master UK Sales'!D:D, 'Master UK Sales'!B:B, B22, 'Master UK Sales'!C:C, C22) -> 5 | J22: =D22-I22 -> 8
B23: 511 Black | C23: 32 | D23: =(E23+F23+G23) -> 11 | G23: 11 | I23: =SUMIFS('Master UK Sales'!D:D, 'Master UK Sales'!B:B, B23, 'Master UK Sales'!C:C, C23) -> 0 | J23: =D23-I23 -> 11
B24: 511 Black | C24: 34 | D24: =(E24+F24+G24) -> 14 | G24: 14 | I24: =SUMIFS('Master UK Sales'!D:D, 'Master UK Sales'!B:B, B24, 'Master UK Sales'!C:C, C24) -> 0 | J24: =D24-I24 -> 14
B25: 511 Black | C25: 36 | D25: =(E25+F25+G25) -> 7 | G25: 7 | I25: =SUMIFS('Master UK Sales'!D:D, 'Master UK Sales'!B:B, B25, 'Master UK Sales'!C:C, C25) -> 0 | J25: =D25-I25 -> 7
B26: 501 Selvedge | C26: 30 | D26: =(E26+F26+G26) -> 6 | G26: 6 | I26: =SUMIFS('Master UK Sales'!D:D, 'Master UK Sales'!B:B, B26, 'Master UK Sales'!C:C, C26) -> 0 | J26: =D26-I26 -> 6
A27: 7 | B27: 501 Selvedge | C27: 32 | D27: =(E27+F27+G27) -> 17 | E27: 0 | F27: 7 | G27: 10 | I27: =SUMIFS('Master UK Sales'!D:D, 'Master UK Sales'!B:B, B27, 'Master UK Sales'!C:C, C27) -> 3 | J27: =D27-I27 -> 14
A28: 7 | B28: 501 Selvedge | C28: 34 | D28: =(E28+F28+G28) -> 22 | E28: 1 | F28: 8 | G28: 13 | I28: =SUMIFS('Master UK Sales'!D:D, 'Master UK Sales'!B:B, B28, 'Master UK Sales'!C:C, C28) -> 9 | J28: =D28-I28 -> 13
A29: 7 | B29: 501 Selvedge | C29: 36 | D29: =(E29+F29+G29) -> 11 | E29: 0 | F29: 5 | G29: 6 | I29: =SUMIFS('Master UK Sales'!D:D, 'Master UK Sales'!B:B, B29, 'Master UK Sales'!C:C, C29) -> 1 | J29: =D29-I29 -> 10
A30: Totoal | D30: =(E30+F30+G30) -> 396 | E30: =(SUM(E2:E29)) -> 60 | F30: =SUM(F2:F29) -> 91 | G30: =SUM(G2:G29) -> 245 | I30: =SUM(I2:I29) -> 134 | J30: =SUM(J2:J29) -> 262

Sheet Master UK Sales
A1: Date | B1: Pant Name | C1: Waist | D1: Quantity Sold | E1: Name | F1: order no | G1: username | H1: sale price | I1: Bump price | J1: refund | K1: payment status | L1: Processed Sales | M1: Received Amount | O1: Total Sales | P1: Total Bump | R1: Ammar | S1: Safie | T1: Abbas | U1: abdullah | V1: Hamza
A2: 13/10/2025 | B2: 501 Selvedge | C2: 34 | D2: 1 | E2: Abbas | H2: 42 | J2: No | K2: Complete | L2: =IF(K2="Processed", H2, "") | M2: =IF(K2="Received", H2, "") | O2: =SUM(H:H) -> 3445.58 | P2: =SUM(I:I) -> 60.11 | R2: =COUNTIF($E:$E,R1) -> 71 | S2: =COUNTIF($E:$E,S1) -> 14 | T2: =COUNTIF($E:$E,T1) -> 35 | U2: =COUNTIF($E:$E,U1) -> 9 | V2: =COUNTIF($E:$E,V1) -> 4
A3: 15/10 | B3: 501 Mid Blue | C3: 34 | D3: 1 | E3: Abbas | H3: 28 | J3: No | K3: Complete | L3: =IF(K3="Processed", H3, "")
A4: 15/10 | B4: 511 Navy Blue | C4: 34 | D4: 1 | E4: Abbas | H4: 22.5 | L4: =IF(K4="Processed", H4, "")
A5: 15/10 | B5: 501 Navy Blue | C5: 36 | D5: 1 | E5: Abbas | H5: 21 | J5: No | K5: Complete | L5: =IF(K5="Processed", H5, "")
A6: 15/10 | B6: 501 Mid Blue | C6: 34 | D6: 1 | E6: Abbas | H6: 22.5 | J6: No | K6: Complete | L6: =IF(K6="Processed", H6, "")
A7: 15/10 | B7: 501 Navy Blue | C7: 34 | D7: 1 | E7: Abbas | H7: 25 | L7: =IF(K7="Processed", H7, "")
A8: 15/10 | B8: 501 Black | C8: 34 | D8: 1 | E8: Abbas | H8: 27.6 | J8: No | K8: Complete | L8: =IF(K8="Processed", H8, "")
A9: 15/10 | B9: 501 Black | C9: 34 | D9: 1 | E9: Abbas | H9: 25.99 | I9: 1.17 | J9: No | K9: Complete | L9: =IF(K9="Processed", H9, "")
A10: 15/10 | B10: 501 Mid Blue | C10: 36 | D10: 1 | E10: Abbas | H10: 25.5 | L10: =IF(K10="Processed", H10, "")
A11: 15/10 | B11: 501 Light Blue | C11: 34 | D11: 1 | E11: Abbas | H11: 25.5 | L11: =IF(K11="Processed", H11, "")
A12: 16/10 | B12: 511 Navy Blue | C12: 32 | D12: 1 | E12: Abbas | H12: 25.4 | I12: 2.22 | L12: =IF(K12="Processed", H12, "")
A13: 16/10 | B13: 501 Light Blue | C13: 34 | D13: 1 | E13: Abbas | H13: 24.5 | L13: =IF(K13="Processed", H13, "")
A14: 17/10 | B14: 511 Navy Blue | C14: 32 | D14: 1 | E14: Abbas | H14: 25 | L14: =IF(K14="Processed", H14, "")
A15: 17/10 | B15: 501 Black | C15: 32 | D15: 1 | E15: Abbas | H15: 24.4 | L15: =IF(K15="Processed", H15, "")
A16: 17/10 | B16: 501 Mid Blue | C16: 34 | D16: 1 | E16: Abbas | H16: 0 | I16: 1.23 | J16: Yes | L16: =IF(K16="Processed", H16, "")
A17: 17/10 | B17: 501 Mid Blue | C17: 36 | D17: 1 | E17: Abbas | H17: 0 | J17: Yes | L17: =IF(K17="Processed", H17, "")
A18: 18/10 | B18: 501 Light Blue | C18: 32 | D18: 1 | E18: Abbas | H18: 25 | I18: 1.23 | L18: =IF(K18="Processed", H18, "")
A19: 18/10 | B19: 501 Light Blue | C19: 36 | D19: 1 | E19: Abbas | H19: 23 | L19: =IF(K19="Processed", H19, "")
A20: 18/10 | B20: 501 Black | C20: 36 | D20: 1 | E20: Abbas | H20: 25.7 | L20: =IF(K20="Processed", H20, "")
A21: 18/10 | B21: 511 Light Blue | C21: 34 | D21: 1 | E21: Abbas | H21: 22.5 | L21: =IF(K21="Processed", H21, "")
A22: 18/10 | B22: 501 Navy Blue | C22: 32 | D22: 1 | E22: Abbas | H22: 0 | J22: Yes | L22: =IF(K22="Processed", H22, "")
A23: 18/10 | B23: 511 Light Blue | C23: 32 | D23: 1 | E23: Abbas | H23: 23 | I23: 2.19 | L23: =IF(K23="Processed", H23, "")
A24: 19/10 | B24: 511 Light Blue | C24: 34 | D24: 1 | E24: Abbas | H24: 27.99 | L24: =IF(K24="Processed", H24, "")
A25: 19/10 | B25: 501 Mid Blue | C25: 32 | D25: 1 | E25: Abbas | H25: 29 | I25: 1.23 | L25: =IF(K25="Processed", H25, "")
A26: 19/10 | B26: 501 Light Blue | C26: 34 | D26: 1 | E26: Abbas | H26: 26.1 | L26: =IF(K26="Processed", H26, "")
A27: 19/10 | B27: 501 Navy Blue | C27: 36 | D27: 1 | E27: Abbas | H27: 0 | J27: Yes | L27: =IF(K27="Processed", H27, "")
A28: 19/10 | B28: 501 Mid Blue | C28: 32 | D28: 1 | E28: Abbas | H28: 25 | L28: =IF(K28="Processed", H28, "")
A29: 19/10 | B29: 511 Light Blue | C29: 36 | D29: 1 | E29: Abbas | H29: 24.8 | L29: =IF(K29="Processed", H29, "")
A30: 19/10 | B30: 511 Navy Blue | C30: 36 | D30: 1 | E30: Abbas | H30: 29 | L30: =IF(K30="Processed", H30, "")
A31: 21/10 | B31: 501 Light Blue | C31: 34 | D31: 1 | E31: Abbas | H31: 24 | L31: =IF(K31="Processed", H31, "")
A32: 21/10 | B32: 511 Light Blue | C32: 36 | D32: 1 | E32: Abbas | H32: 25
A33: 21/10 | B33: 511 Light Blue | C33: 36 | D33: 1 | E33: Abbas | H33: 24 | I33: 1.17 | L33: =IF(K33="Processed", H33, "")
A34: 22/10 | B34: 501 Mid Blue | C34: 34 | D34: 1 | E34: Abbas | H34: 29 | L34: =IF(K34="Processed", H34, "")
A35: 22/10 | B35: 511 Navy Blue | C35: 36 | D35: 1 | E35: Safie | H35: 22 | I35: 1.23 | L35: =IF(K35="Processed", H35, "")
A36: 22/10 | B36: 501 Navy Blue | C36: 34 | D36: 1 | E36: Abbas | H36: 25 | L36: =IF(K36="Processed", H36, "")
A37: 22/10 | B37: 501 Light Blue | C37: 32 | D37: 1 | E37: Abbas | H37: 25 | L37: =IF(K37="Processed", H37, "")
A38: 23/10 | B38: 501 Light Blue | C38: 34 | D38: 1 | E38: Ammar | H38: 26 | L38: =IF(K38="Processed", H38, "")
A39: 24/10 | B39: 511 Navy Blue | C39: 34 | D39: 1 | E39: Ammar | H39: 29 | L39: =IF(K39="Processed", H39, "")
A40: 25/10 | B40: 501 Navy Blue | C40: 34 | D40: 1 | E40: Ammar | H40: 29 | L40: =IF(K40="Processed", H40, "")
...

Sheet Copy of UK-London
A1: 0 | B1: Pant Name | C1: Waist | D1: Total Stock | E1: Shipment 3 | F1: Shipment 14 | G1: Shipment 15 | H1: Shipment 16 | I1: Shipment 17 | J1: Shipment 18 | K1: Shipment 19 | L1: Shipment 20 | M1: Manchester | N1: Shipment 21 | O1: Shipment 22 | P1: Shipment 23 | Q1: Shipment 24 | R1: Shipment 25 | S1: Shipment 26 | T1: Sold (auto) | U1: Current Stock | V1: Photos Captured
A2: 501
A3: 1 | B3: 501 Light Blue | C3: 30 | D3: =(E3+F3+G3+H3+I3+J3+K3+L3+M3+N3+O3+P3+Q3+R3+S3) -> 5 | I3: 5 | T3: =SUMIFS('UK London sales'!D:D, 'UK London sales'!B:B, B3, 'UK London sales'!C:C, C3) -> 4 | U3: =D3-T3 -> 1 | V3: 0
A4: 2 | B4: 501 Light Blue | C4: 32 | D4: =(E4+F4+G4+H4+I4+J4+K4+L4+M4+N4+O4+P4+Q4+R4+S4) -> 100 | E4: 33 | F4: 8 | I4: 10 | J4: 10 | K4: 12 | L4: 13 | M4: 2 | O4: 12 | T4: =SUMIFS('UK London sales'!D:D, 'UK London sales'!B:B, B4, 'UK London sales'!C:C, C4) -> 100 | U4: =D4-T4 -> 0
A5: 3 | B5: 501 Light Blue | C5: 34 | D5: =(E5+F5+G5+H5+I5+J5+K5+L5+M5+N5+O5+P5+Q5+R5+S5) -> 107 | E5: 33 | F5: 17 | I5: 10 | J5: 10 | K5: 9 | L5: 13 | O5: 12 | Q5: 3 | T5: =SUMIFS('UK London sales'!D:D, 'UK London sales'!B:B, B5, 'UK London sales'!C:C, C5) -> 107 | U5: =D5-T5 -> 0
A6: 4 | B6: 501 Light Blue | C6: 36 | D6: =(E6+F6+G6+H6+I6+J6+K6+L6+M6+N6+O6+P6+Q6+R6+S6) -> 81 | E6: 20 | F6: 8 | I6: 9 | J6: 13 | K6: 9 | L6: 6 | M6: 3 | O6: 12 | Q6: 1 | T6: =SUMIFS('UK London sales'!D:D, 'UK London sales'!B:B, B6, 'UK London sales'!C:C, C6) -> 81 | U6: =D6-T6 -> 0
A7: 6 | B7: 501 Mid Blue | C7: 30 | D7: =(E7+F7+G7+H7+I7+J7+K7+L7+M7+N7+O7+P7+Q7+R7+S7) -> 5 | I7: 5 | T7: =SUMIFS('UK London sales'!D:D, 'UK London sales'!B:B, B7, 'UK London sales'!C:C, C7) -> 5 | U7: =D7-T7 -> 0
A8: 5 | B8: 501 Mid Blue L30 | C8: 32 | D8: =(E8+F8+G8+H8+I8+J8+K8+L8+M8+N8+O8+P8+Q8+R8+S8) -> 10 | S8: 10 | T8: =SUMIFS('UK London sales'!D:D, 'UK London sales'!B:B, B8, 'UK London sales'!C:C, C8) -> 8 | U8: =D8-T8 -> 2 | V8: 10
A9: 7 | B9: 501 Mid Blue | C9: 32 | D9: =(E9+F9+G9+H9+I9+J9+K9+L9+M9+N9+O9+P9+Q9+R9+S9) -> 40 | G9: 3 | H9: 10 | I9: 5 | N9: 12 | R9: 10 | T9: =SUMIFS('UK London sales'!D:D, 'UK London sales'!B:B, B9, 'UK London sales'!C:C, C9) -> 40 | U9: =D9-T9 -> 0 | V9: 0
A10: 8 | B10: 501 Mid Blue | C10: 34 | D10: =(E10+F10+G10+H10+I10+J10+K10+L10+M10+N10+O10+P10+Q10+R10+S10) -> 72 | G10: 19 | H10: 10 | I10: 9 | M10: 1 | N10: 13 | R10: 10 | S10: 10 | T10: =SUMIFS('UK London sales'!D:D, 'UK London sales'!B:B, B10, 'UK London sales'!C:C, C10) -> 72 | U10: =D10-T10 -> 0
A11: 9 | B11: 501 Mid Blue | C11: 36 | D11: =(E11+F11+G11+H11+I11+J11+K11+L11+M11+N11+O11+P11+Q11+R11+S11) -> 59 | G11: 11 | H11: 10 | I11: 11 | N11: 5 | Q11: 2 | R11: 10 | S11: 10 | T11: =SUMIFS('UK London sales'!D:D, 'UK London sales'!B:B, B11, 'UK London sales'!C:C, C11) -> 54 | U11: =D11-T11 -> 5 | V11: 10
A12: 10 | B12: 501 Navy Blue | C12: 30 | D12: =(E12+F12+G12+H12+I12+J12+K12+L12+M12+N12+O12+P12+Q12+R12+S12) -> 5 | I12: 5 | T12: =SUMIFS('UK London sales'!D:D, 'UK London sales'!B:B, B12, 'UK London sales'!C:C, C12) -> 8 | U12: =D12-T12 -> -3
A13: 11 | B13: 501 Navy Blue | C13: 32 | D13: =(E13+F13+G13+H13+I13+J13+K13+L13+M13+N13+O13+P13+Q13+R13+S13) -> 83 | E13: 21 | F13: 10 | G13: 10 | H13: 10 | I13: 11 | M13: 10 | Q13: 11 | T13: =SUMIFS('UK London sales'!D:D, 'UK London sales'!B:B, B13, 'UK London sales'!C:C, C13) -> 89 | U13: =D13-T13 -> -6
A14: 12 | B14: 501 Navy Blue | C14: 34 | D14: =(E14+F14+G14+H14+I14+J14+K14+L14+M14+N14+O14+P14+Q14+R14+S14) -> 91 | E14: 23 | F14: 10 | G14: 10 | H14: 10 | I14: 11 | N14: 15 | Q14: 12 | T14: =SUMIFS('UK London sales'!D:D, 'UK London sales'!B:B, B14, 'UK London sales'!C:C, C14) -> 97 | U14: =D14-T14 -> -6
A15: 13 | B15: 501 Navy Blue | C15: 36 | D15: =(E15+F15+G15+H15+I15+J15+K15+L15+M15+N15+O15+P15+Q15+R15+S15) -> 54 | E15: 8 | F15: 10 | G15: 10 | H15: 10 | I15: 5 | Q15: 11 | T15: =SUMIFS('UK London sales'!D:D, 'UK London sales'!B:B, B15, 'UK London sales'!C:C, C15) -> 59 | U15: =D15-T15 -> -5
A16: 17 | B16: 501 Grey | C16: 32 | D16: =(E16+F16+G16+H16+I16+J16+K16+L16+M16+N16+O16+P16+Q16+R16+S16) -> 20 | P16: 11 | Q16: 9 | T16: =SUMIFS('UK London sales'!D:D, 'UK London sales'!B:B, B16, 'UK London sales'!C:C, C16) -> 20 | U16: =D16-T16 -> 0 | V16: 0
A17: 18 | B17: 501 Grey | C17: 34 | D17: =(E17+F17+G17+H17+I17+J17+K17+L17+M17+N17+O17+P17+Q17+R17+S17) -> 21 | P17: 11 | Q17: 10 | T17: =SUMIFS('UK London sales'!D:D, 'UK London sales'!B:B, B17, 'UK London sales'!C:C, C17) -> 26 | U17: =D17-T17 -> -5
A18: 19 | B18: 501 Grey | C18: 36 | D18: =(E18+F18+G18+H18+I18+J18+K18+L18+M18+N18+O18+P18+Q18+R18+S18) -> 22 | P18: 11 | Q18: 11 | T18: =SUMIFS('UK London sales'!D:D, 'UK London sales'!B:B, B18, 'UK London sales'!C:C, C18) -> 25 | U18: =D18-T18 -> -3
A19: 14 | B19: 501 Black | C19: 32 | D19: =(E19+F19+G19+H19+I19+J19+K19+L19+M19+N19+O19+P19+Q19+R19+S19) -> 38 | E19: 9 | J19: 10 | K19: 13 | M19: 1 | P19: 3 | Q19: 2 | T19: =SUMIFS('UK London sales'!D:D, 'UK London sales'!B:B, B19, 'UK London sales'!C:C, C19) -> 37 | U19: =D19-T19 -> 1
A20: 15 | B20: 501 Black | C20: 34 | D20: =(E20+F20+G20+H20+I20+J20+K20+L20+M20+N20+O20+P20+Q20+R20+S20) -> 27 | J20: 10 | K20: 14 | P20: 3 | T20: =SUMIFS('UK London sales'!D:D, 'UK London sales'!B:B, B20, 'UK London sales'!C:C, C20) -> 27 | U20: =D20-T20 -> 0
A21: 16 | B21: 501 Black | C21: 36 | D21: =(E21+F21+G21+H21+I21+J21+K21+L21+M21+N21+O21+P21+Q21+R21+S21) -> 19 | J21: 9 | K21: 7 | P21: 3 | T21: =SUMIFS('UK London sales'!D:D, 'UK London sales'!B:B, B21, 'UK London sales'!C:C, C21) -> 19 | U21: =D21-T21 -> 0
A22: 511
A23: 22 | B23: 511 Light Blue | C23: 32 | D23: =(E23+F23+G23+H23+I23+J23+K23+L23+M23+N23+O23+P23+Q23+R23+S23) -> 33 | K23: 15 | O23: 18 | T23: =SUMIFS('UK London sales'!D:D, 'UK London sales'!B:B, B23, 'UK London sales'!C:C, C23) -> 33 | U23: =D23-T23 -> 0
A24: 23 | B24: 511 Light Blue | C24: 34 | D24: =(E24+F24+G24+H24+I24+J24+K24+L24+M24+N24+O24+P24+Q24+R24+S24) -> 34 | K24: 16 | O24: 18 | T24: =SUMIFS('UK London sales'!D:D, 'UK London sales'!B:B, B24, 'UK London sales'!C:C, C24) -> 34 | U24: =D24-T24 -> 0
A25: 24 | B25: 511 Light Blue | C25: 36 | D25: =(E25+F25+G25+H25+I25+J25+K25+L25+M25+N25+O25+P25+Q25+R25+S25) -> 0 | T25: =SUMIFS('UK London sales'!D:D, 'UK London sales'!B:B, B25, 'UK London sales'!C:C, C25) -> 0 | U25: =D25-T25 -> 0
A26: 25 | B26: 511 Mid Blue | C26: 32 | D26: =(E26+F26+G26+H26+I26+J26+K26+L26+M26+N26+O26+P26+Q26+R26+S26) -> 37 | G26: 12 | M26: 5 | N26: 10 | R26: 10 | T26: =SUMIFS('UK London sales'!D:D, 'UK London sales'!B:B, B26, 'UK London sales'!C:C, C26) -> 34 | U26: =D26-T26 -> 3
A27: 26 | B27: 511 Mid Blue | C27: 34 | D27: =(E27+F27+G27+H27+I27+J27+K27+L27+M27+N27+O27+P27+Q27+R27+S27) -> 42 | E27: 4 | G27: 10 | M27: 7 | N27: 10 | Q27: 1 | R27: 10 | T27: =SUMIFS('UK London sales'!D:D, 'UK London sales'!B:B, B27, 'UK London sales'!C:C, C27) -> 42 | U27: =D27-T27 -> 0
A28: 27 | B28: 511 Mid Blue | C28: 36 | D28: =(E28+F28+G28+H28+I28+J28+K28+L28+M28+N28+O28+P28+Q28+R28+S28) -> 28 | G28: 11 | M28: 12 | R28: 5 | T28: =SUMIFS('UK London sales'!D:D, 'UK London sales'!B:B, B28, 'UK London sales'!C:C, C28) -> 29 | U28: =D28-T28 -> -1
A29: 28 | B29: 511 Navy Blue | C29: 32 | D29: =(E29+F29+G29+H29+I29+J29+K29+L29+M29+N29+O29+P29+Q29+R29+S29) -> 72 | E29: 6 | F29: 8 | G29: 16 | H29: 17 | N29: 10 | Q29: 5 | S29: 10 | T29: =SUMIFS('UK London sales'!D:D, 'UK London sales'!B:B, B29, 'UK London sales'!C:C, C29) -> 72 | U29: =D29-T29 -> 0 | V29: 7
A30: 29 | B30: 511 Navy Blue | C30: 34 | D30: =(E30+F30+G30+H30+I30+J30+K30+L30+M30+N30+O30+P30+Q30+R30+S30) -> 90 | E30: 12 | F30: 15 | G30: 12 | H30: 18 | N30: 10 | Q30: 13 | S30: 10 | T30: =SUMIFS('UK London sales'!D:D, 'UK London sales'!B:B, B30, 'UK London sales'!C:C, C30) -> 90 | U30: =D30-T30 -> 0 | V30: 3
A31: 30 | B31: 511 Navy Blue | C31: 36 | D31: =(E31+F31+G31+H31+I31+J31+K31+L31+M31+N31+O31+P31+Q31+R31+S31) -> 47 | E31: 8 | F31: 9 | M31: 6 | N31: 10 | Q31: 4 | S31: 10 | T31: =SUMIFS('UK London sales'!D:D, 'UK London sales'!B:B, B31, 'UK London sales'!C:C, C31) -> 47 | U31: =D31-T31 -> 0
A32: 37 | B32: 511 Grey | C32: 30 | D32: =(E32+F32+G32+H32+I32+J32+K32+L32+M32+N32+O32+P32+Q32+R32+S32) -> 14 | J32: 6 | K32: 5 | Q32: 1 | S32: 2 | T32: =SUMIFS('UK London sales'!D:D, 'UK London sales'!B:B, B32, 'UK London sales'!C:C, C32) -> 12 | U32: =D32-T32 -> 2
A33: 38 | B33: 511 Grey | C33: 32 | D33: =(E33+F33+G33+H33+I33+J33+K33+L33+M33+N33+O33+P33+Q33+R33+S33) -> 63 | J33: 10 | K33: 10 | L33: 12 | N33: 11 | P33: 12 | S33: 8 | T33: =SUMIFS('UK London sales'!D:D, 'UK London sales'!B:B, B33, 'UK London sales'!C:C, C33) -> 63 | U33: =D33-T33 -> 0
A34: 39 | B34: 511 Grey | C34: 34 | D34: =(E34+F34+G34+H34+I34+J34+K34+L34+M34+N34+O34+P34+Q34+R34+S34) -> 85 | J34: 10 | K34: 10 | L34: 14 | N34: 37 | P34: 5 | Q34: 2 | S34: 7 | T34: =SUMIFS('UK London sales'!D:D, 'UK London sales'!B:B, B34, 'UK London sales'!C:C, C34) -> 84 | U34: =D34-T34 -> 1
A35: 40 | B35: 511 Grey | C35: 36 | D35: =(E35+F35+G35+H35+I35+J35+K35+L35+M35+N35+O35+P35+Q35+R35+S35) -> 28 | J35: 10 | K35: 5 | L35: 5 | S35: 8 | T35: =SUMIFS('UK London sales'!D:D, 'UK London sales'!B:B, B35, 'UK London sales'!C:C, C35) -> 28 | U35: =D35-T35 -> 0
A36: 41 | B36: 511 Grey | C36: 38 | D36: =(E36+F36+G36+H36+I36+J36+K36+L36+M36+N36+O36+P36+Q36+R36+S36) -> 2 | S36: 2 | T36: =SUMIFS('UK London sales'!D:D, 'UK London sales'!B:B, B36, 'UK London sales'!C:C, C36) -> 2 | U36: =D36-T36 -> 0
A37: 31 | B37: 511 Black | C37: 32 | D37: =(E37+F37+G37+H37+I37+J37+K37+L37+M37+N37+O37+P37+Q37+R37+S37) -> 48 | E37: 11 | I37: 12 | J37: 11 | M37: 2 | N37: 12 | T37: =SUMIFS('UK London sales'!D:D, 'UK London sales'!B:B, B37, 'UK London sales'!C:C, C37) -> 48 | U37: =D37-T37 -> 0
A38: 32 | B38: 511 Black | C38: 34 | D38: =(E38+F38+G38+H38+I38+J38+K38+L38+M38+N38+O38+P38+Q38+R38+S38) -> 47 | E38: 14 | I38: 12 | J38: 12 | Q38: 9 | T38: =SUMIFS('UK London sales'!D:D, 'UK London sales'!B:B, B38, 'UK London sales'!C:C, C38) -> 47 | U38: =D38-T38 -> 0
A39: 33 | B39: 511 Black | C39: 36 | D39: =(E39+F39+G39+H39+I39+J39+K39+L39+M39+N39+O39+P39+Q39+R39+S39) -> 42 | E39: 7 | I39: 12 | J39: 12 | N39: 3 | Q39: 8 | T39: =SUMIFS('UK London sales'!D:D, 'UK London sales'!B:B, B39, 'UK London sales'!C:C, C39) -> 42 | U39: =D39-T39 -> 0
A40: 34 | B40: 511 Light Blue L30 | C40: 32 | D40: =(E40+F40+G40+H40+I40+J40+K40+L40+M40+N40+O40+P40+Q40+R40+S40) -> 11 | R40: 11 | T40: =SUMIFS('UK London sales'!D:D, 'UK London sales'!B:B, B40, 'UK London sales'!C:C, C40) -> 3 | U40: =D40-T40 -> 8
...

Sheet UK-London
A1: 0 | B1: Pant Name | C1: Waist | D1: Total Stock | E1: Shipment 3 | F1: Shipment 14 | G1: Shipment 15 | H1: Shipment 16 | I1: Shipment 17 | J1: Shipment 18 | K1: Shipment 19 | L1: Shipment 20 | M1: Manchester | N1: Shipment 21 | O1: Shipment 22 | P1: Shipment 23 | Q1: Shipment 24 | R1: Shipment 25 | S1: Shipment 26 | T1: Shipment 27 | U1: Sold (auto) | V1: Current Stock
A2: 501
A3: 1 | B3: 501 Light Blue | C3: 30 | D3: =(E3+F3+G3+H3+I3+J3+K3+L3+M3+N3+O3+P3+Q3+R3+S3+T3) -> 5 | I3: 5 | U3: =SUMIFS('UK London sales'!D:D, 'UK London sales'!B:B, B3, 'UK London sales'!C:C, C3) -> 4 | V3: =D3-U3 -> 1
A4: 2 | B4: 501 Light Blue | C4: 32 | D4: =(E4+F4+G4+H4+I4+J4+K4+L4+M4+N4+O4+P4+Q4+R4+S4+T4) -> 100 | E4: 33 | F4: 8 | I4: 10 | J4: 10 | K4: 12 | L4: 13 | M4: 2 | O4: 12 | U4: =SUMIFS('UK London sales'!D:D, 'UK London sales'!B:B, B4, 'UK London sales'!C:C, C4) -> 100 | V4: =D4-U4 -> 0
A5: 3 | B5: 501 Light Blue | C5: 34 | D5: =(E5+F5+G5+H5+I5+J5+K5+L5+M5+N5+O5+P5+Q5+R5+S5+T5) -> 107 | E5: 33 | F5: 17 | I5: 10 | J5: 10 | K5: 9 | L5: 13 | O5: 12 | Q5: 3 | U5: =SUMIFS('UK London sales'!D:D, 'UK London sales'!B:B, B5, 'UK London sales'!C:C, C5) -> 107 | V5: =D5-U5 -> 0
A6: 4 | B6: 501 Light Blue | C6: 36 | D6: =(E6+F6+G6+H6+I6+J6+K6+L6+M6+N6+O6+P6+Q6+R6+S6+T6) -> 81 | E6: 20 | F6: 8 | I6: 9 | J6: 13 | K6: 9 | L6: 6 | M6: 3 | O6: 12 | Q6: 1 | U6: =SUMIFS('UK London sales'!D:D, 'UK London sales'!B:B, B6, 'UK London sales'!C:C, C6) -> 81 | V6: =D6-U6 -> 0
A7: 6 | B7: 501 Mid Blue | C7: 30 | D7: =(E7+F7+G7+H7+I7+J7+K7+L7+M7+N7+O7+P7+Q7+R7+S7+T7) -> 5 | I7: 5 | U7: =SUMIFS('UK London sales'!D:D, 'UK London sales'!B:B, B7, 'UK London sales'!C:C, C7) -> 5 | V7: =D7-U7 -> 0
A8: 5 | B8: 501 Mid Blue L30 | C8: 32 | D8: =(E8+F8+G8+H8+I8+J8+K8+L8+M8+N8+O8+P8+Q8+R8+S8+T8) -> 10 | S8: 10 | U8: =SUMIFS('UK London sales'!D:D, 'UK London sales'!B:B, B8, 'UK London sales'!C:C, C8) -> 8 | V8: =D8-U8 -> 2
A9: 7 | B9: 501 Mid Blue | C9: 32 | D9: =(E9+F9+G9+H9+I9+J9+K9+L9+M9+N9+O9+P9+Q9+R9+S9+T9) -> 40 | G9: 3 | H9: 10 | I9: 5 | N9: 12 | R9: 10 | U9: =SUMIFS('UK London sales'!D:D, 'UK London sales'!B:B, B9, 'UK London sales'!C:C, C9) -> 40 | V9: =D9-U9 -> 0
A10: 8 | B10: 501 Mid Blue | C10: 34 | D10: =(E10+F10+G10+H10+I10+J10+K10+L10+M10+N10+O10+P10+Q10+R10+S10+T10) -> 72 | G10: 19 | H10: 10 | I10: 9 | M10: 1 | N10: 13 | R10: 10 | S10: 10 | U10: =SUMIFS('UK London sales'!D:D, 'UK London sales'!B:B, B10, 'UK London sales'!C:C, C10) -> 72 | V10: =D10-U10 -> 0
A11: 9 | B11: 501 Mid Blue | C11: 36 | D11: =(E11+F11+G11+H11+I11+J11+K11+L11+M11+N11+O11+P11+Q11+R11+S11+T11) -> 59 | G11: 11 | H11: 10 | I11: 11 | N11: 5 | Q11: 2 | R11: 10 | S11: 10 | U11: =SUMIFS('UK London sales'!D:D, 'UK London sales'!B:B, B11, 'UK London sales'!C:C, C11) -> 54 | V11: =D11-U11 -> 5
A12: 10 | B12: 501 Navy Blue | C12: 30 | D12: =(E12+F12+G12+H12+I12+J12+K12+L12+M12+N12+O12+P12+Q12+R12+S12+T12) -> 8 | I12: 5 | T12: 3 | U12: =SUMIFS('UK London sales'!D:D, 'UK London sales'!B:B, B12, 'UK London sales'!C:C, C12) -> 8 | V12: =D12-U12 -> 0
A13: 11 | B13: 501 Navy Blue | C13: 32 | D13: =(E13+F13+G13+H13+I13+J13+K13+L13+M13+N13+O13+P13+Q13+R13+S13+T13) -> 88 | E13: 21 | F13: 10 | G13: 10 | H13: 10 | I13: 11 | M13: 10 | Q13: 11 | T13: 5 | U13: =SUMIFS('UK London sales'!D:D, 'UK London sales'!B:B, B13, 'UK London sales'!C:C, C13) -> 89 | V13: =D13-U13 -> -1
A14: 12 | B14: 501 Navy Blue | C14: 34 | D14: =(E14+F14+G14+H14+I14+J14+K14+L14+M14+N14+O14+P14+Q14+R14+S14+T14) -> 97 | E14: 23 | F14: 10 | G14: 10 | H14: 10 | I14: 11 | N14: 15 | Q14: 12 | T14: 6 | U14: =SUMIFS('UK London sales'!D:D, 'UK London sales'!B:B, B14, 'UK London sales'!C:C, C14) -> 97 | V14: =D14-U14 -> 0
A15: 13 | B15: 501 Navy Blue | C15: 36 | D15: =(E15+F15+G15+H15+I15+J15+K15+L15+M15+N15+O15+P15+Q15+R15+S15+T15) -> 59 | E15: 8 | F15: 10 | G15: 10 | H15: 10 | I15: 5 | Q15: 11 | T15: 5 | U15: =SUMIFS('UK London sales'!D:D, 'UK London sales'!B:B, B15, 'UK London sales'!C:C, C15) -> 59 | V15: =D15-U15 -> 0
A16: 14 | B16: 501 Navy Blue | C16: 38 | D16: =(E16+F16+G16+H16+I16+J16+K16+L16+M16+N16+O16+P16+Q16+R16+S16+T16) -> 3 | T16: 3 | U16: =SUMIFS('UK London sales'!D:D, 'UK London sales'!B:B, B16, 'UK London sales'!C:C, C16) -> 2 | V16: =D16-U16 -> 1
A17: 15 | B17: 501 Navy Blue | C17: 40 | D17: =(E17+F17+G17+H17+I17+J17+K17+L17+M17+N17+O17+P17+Q17+R17+S17+T17) -> 2 | T17: 2 | U17: =SUMIFS('UK London sales'!D:D, 'UK London sales'!B:B, B17, 'UK London sales'!C:C, C17) -> 2 | V17: =D17-U17 -> 0
A18: 16 | B18: 501 Grey | C18: 30 | D18: =(E18+F18+G18+H18+I18+J18+K18+L18+M18+N18+O18+P18+Q18+R18+S18+T18) -> 3 | T18: 3 | U18: =SUMIFS('UK London sales'!D:D, 'UK London sales'!B:B, B18, 'UK London sales'!C:C, C18) -> 2 | V18: =D18-U18 -> 1
A19: 17 | B19: 501 Grey | C19: 32 | D19: =(E19+F19+G19+H19+I19+J19+K19+L19+M19+N19+O19+P19+Q19+R19+S19+T19) -> 25 | P19: 11 | Q19: 9 | T19: 5 | U19: =SUMIFS('UK London sales'!D:D, 'UK London sales'!B:B, B19, 'UK London sales'!C:C, C19) -> 20 | V19: =D19-U19 -> 5
A20: 18 | B20: 501 Grey | C20: 34 | D20: =(E20+F20+G20+H20+I20+J20+K20+L20+M20+N20+O20+P20+Q20+R20+S20+T20) -> 26 | P20: 11 | Q20: 10 | T20: 5 | U20: =SUMIFS('UK London sales'!D:D, 'UK London sales'!B:B, B20, 'UK London sales'!C:C, C20) -> 26 | V20: =D20-U20 -> 0
A21: 19 | B21: 501 Grey | C21: 36 | D21: =(E21+F21+G21+H21+I21+J21+K21+L21+M21+N21+O21+P21+Q21+R21+S21+T21) -> 28 | P21: 11 | Q21: 11 | T21: 6 | U21: =SUMIFS('UK London sales'!D:D, 'UK London sales'!B:B, B21, 'UK London sales'!C:C, C21) -> 25 | V21: =D21-U21 -> 3
A22: 20 | B22: 501 Grey | C22: 38 | D22: =(E22+F22+G22+H22+I22+J22+K22+L22+M22+N22+O22+P22+Q22+R22+S22+T22) -> 2 | T22: 2 | U22: =SUMIFS('UK London sales'!D:D, 'UK London sales'!B:B, B22, 'UK London sales'!C:C, C22) -> 0 | V22: =D22-U22 -> 2
A23: 21 | B23: 501 Grey | C23: 40 | D23: =(E23+F23+G23+H23+I23+J23+K23+L23+M23+N23+O23+P23+Q23+R23+S23+T23) -> 3 | T23: 3 | U23: =SUMIFS('UK London sales'!D:D, 'UK London sales'!B:B, B23, 'UK London sales'!C:C, C23) -> 3 | V23: =D23-U23 -> 0
A24: 22 | B24: 501 Black | C24: 32 | D24: =(E24+F24+G24+H24+I24+J24+K24+L24+M24+N24+O24+P24+Q24+R24+S24+T24) -> 38 | E24: 9 | J24: 10 | K24: 13 | M24: 1 | P24: 3 | Q24: 2 | U24: =SUMIFS('UK London sales'!D:D, 'UK London sales'!B:B, B24, 'UK London sales'!C:C, C24) -> 37 | V24: =D24-U24 -> 1
A25: 23 | B25: 501 Black | C25: 34 | D25: =(E25+F25+G25+H25+I25+J25+K25+L25+M25+N25+O25+P25+Q25+R25+S25+T25) -> 27 | J25: 10 | K25: 14 | P25: 3 | U25: =SUMIFS('UK London sales'!D:D, 'UK London sales'!B:B, B25, 'UK London sales'!C:C, C25) -> 27 | V25: =D25-U25 -> 0
A26: 24 | B26: 501 Black | C26: 36 | D26: =(E26+F26+G26+H26+I26+J26+K26+L26+M26+N26+O26+P26+Q26+R26+S26+T26) -> 19 | J26: 9 | K26: 7 | P26: 3 | U26: =SUMIFS('UK London sales'!D:D, 'UK London sales'!B:B, B26, 'UK London sales'!C:C, C26) -> 19 | V26: =D26-U26 -> 0
A27: 502
A28: 25 | B28: 502 Navy Blue | C28: 30 | D28: =(E28+F28+G28+H28+I28+J28+K28+L28+M28+N28+O28+P28+Q28+R28+S28+T28) -> 2 | T28: 2 | U28: =SUMIFS('UK London sales'!D:D, 'UK London sales'!B:B, B28, 'UK London sales'!C:C, C28) -> 2 | V28: =D28-U28 -> 0
A29: 26 | B29: 502 Navy Blue | C29: 32 | D29: =(E29+F29+G29+H29+I29+J29+K29+L29+M29+N29+O29+P29+Q29+R29+S29+T29) -> 7 | T29: 7 | U29: =SUMIFS('UK London sales'!D:D, 'UK London sales'!B:B, B29, 'UK London sales'!C:C, C29) -> 7 | V29: =D29-U29 -> 0
A30: 27 | B30: 502 Navy Blue | C30: 34 | D30: =(E30+F30+G30+H30+I30+J30+K30+L30+M30+N30+O30+P30+Q30+R30+S30+T30) -> 7 | T30: 7 | U30: =SUMIFS('UK London sales'!D:D, 'UK London sales'!B:B, B30, 'UK London sales'!C:C, C30) -> 7 | V30: =D30-U30 -> 0
A31: 28 | B31: 502 Navy Blue | C31: 36 | D31: =(E31+F31+G31+H31+I31+J31+K31+L31+M31+N31+O31+P31+Q31+R31+S31+T31) -> 7 | T31: 7 | U31: =SUMIFS('UK London sales'!D:D, 'UK London sales'!B:B, B31, 'UK London sales'!C:C, C31) -> 2 | V31: =D31-U31 -> 5
A32: 29 | B32: 502 Navy Blue | C32: 38 | D32: =(E32+F32+G32+H32+I32+J32+K32+L32+M32+N32+O32+P32+Q32+R32+S32+T32) -> 2 | T32: 2 | U32: =SUMIFS('UK London sales'!D:D, 'UK London sales'!B:B, B32, 'UK London sales'!C:C, C32) -> 2 | V32: =D32-U32 -> 0
A33: 30 | B33: 502 Black | C33: 32 | D33: =(T33) -> 6 | J33: 9 | K33: 7 | P33: 3 | T33: 6 | U33: =SUMIFS('UK London sales'!D:D, 'UK London sales'!B:B, B33, 'UK London sales'!C:C, C33) -> 6 | V33: =D33-U33 -> 0
A34: 31 | B34: 502 Black | C34: 34 | D34: =(E34+F34+G34+H34+I34+J34+K34+L34+M34+N34+O34+P34+Q34+R34+S34+T34) -> 5 | T34: 5 | U34: =SUMIFS('UK London sales'!D:D, 'UK London sales'!B:B, B34, 'UK London sales'!C:C, C34) -> 5 | V34: =D34-U34 -> 0
A35: 32 | B35: 502 Black | C35: 36 | D35: =(E35+F35+G35+H35+I35+J35+K35+L35+M35+N35+O35+P35+Q35+R35+S35+T35) -> 7 | T35: 7 | U35: =SUMIFS('UK London sales'!D:D, 'UK London sales'!B:B, B35, 'UK London sales'!C:C, C35) -> 7 | V35: =D35-U35 -> 0
A36: 33 | B36: 502 Black | C36: 38 | D36: =(E36+F36+G36+H36+I36+J36+K36+L36+M36+N36+O36+P36+Q36+R36+S36+T36) -> 4 | T36: 4 | U36: =SUMIFS('UK London sales'!D:D, 'UK London sales'!B:B, B36, 'UK London sales'!C:C, C36) -> 4 | V36: =D36-U36 -> 0
A37: 34 | B37: 502 Black | C37: 40 | D37: =(E37+F37+G37+H37+I37+J37+K37+L37+M37+N37+O37+P37+Q37+R37+S37+T37) -> 3 | T37: 3 | U37: =SUMIFS('UK London sales'!D:D, 'UK London sales'!B:B, B37, 'UK London sales'!C:C, C37) -> 3 | V37: =D37-U37 -> 0
A38: 511
A39: 35 | B39: 511 Light Blue | C39: 32 | D39: =(E39+F39+G39+H39+I39+J39+K39+L39+M39+N39+O39+P39+Q39+R39+S39+T39) -> 33 | K39: 15 | O39: 18 | U39: =SUMIFS('UK London sales'!D:D, 'UK London sales'!B:B, B39, 'UK London sales'!C:C, C39) -> 33 | V39: =D39-U39 -> 0
A40: 36 | B40: 511 Light Blue | C40: 34 | D40: =(E40+F40+G40+H40+I40+J40+K40+L40+M40+N40+O40+P40+Q40+R40+S40) -> 34 | K40: 16 | O40: 18 | U40: =SUMIFS('UK London sales'!D:D, 'UK London sales'!B:B, B40, 'UK London sales'!C:C, C40) -> 34 | V40: =D40-U40 -> 0
...

Sheet Shirts + Socks
B1: Pant Name | C1: Waist | D1: Total Stock | E1: Shipment 3 | F1: Shipment 14 | G1: Shipment 15 | H1: Shipment 16 | I1: Shipment 17 | J1: Shipment 18 | K1: Shipment 19 | L1: Shipment 20 | M1: Manchester | N1: Shipment 21 | O1: Shipment 22 | P1: Shipment 23 | Q1: Shipment 24 | R1: Shipment 26 | S1: Sold (auto) | T1: Current Stock
A2: SHIRTS
A3: 51 | B3: Boss Shirt Blue | C3: S | D3: =R3 -> 1 | R3: 1 | S3: =SUMIFS('UK London sales'!D:D, 'UK London sales'!B:B, B3, 'UK London sales'!C:C, C3) -> 0 | T3: =D3-S3 -> 1
A4: 52 | B4: Boss Shirt Blue | C4: M | D4: =R4 -> 2 | R4: 2 | S4: =SUMIFS('UK London sales'!D:D, 'UK London sales'!B:B, B4, 'UK London sales'!C:C, C4) -> 0 | T4: =D4-S4 -> 2
A5: 53 | B5: Boss Shirt Blue | C5: L | D5: =R5 -> 1 | R5: 1 | S5: =SUMIFS('UK London sales'!D:D, 'UK London sales'!B:B, B5, 'UK London sales'!C:C, C5) -> 0 | T5: =D5-S5 -> 1
A6: 54 | B6: Boss Shirt Blue | C6: XL | D6: =R6 -> 1 | R6: 1 | S6: =SUMIFS('UK London sales'!D:D, 'UK London sales'!B:B, B6, 'UK London sales'!C:C, C6) -> 0 | T6: =D6-S6 -> 1
A7: 55 | B7: Polo Shirt Navy | C7: S | D7: =R7 -> 1 | R7: 1 | S7: =SUMIFS('UK London sales'!D:D, 'UK London sales'!B:B, B7, 'UK London sales'!C:C, C7) -> 0 | T7: =D7-S7 -> 1
A8: 56 | B8: Polo Shirt Navy | C8: M | D8: =R8 -> 0 | R8: 0 | S8: =SUMIFS('UK London sales'!D:D, 'UK London sales'!B:B, B8, 'UK London sales'!C:C, C8) -> 0 | T8: =D8-S8 -> 0
A9: 57 | B9: Polo Shirt Navy | C9: L | D9: =R9 -> 1 | R9: 1 | S9: =SUMIFS('UK London sales'!D:D, 'UK London sales'!B:B, B9, 'UK London sales'!C:C, C9) -> 0 | T9: =D9-S9 -> 1
A10: 58 | B10: Polo Shirt Navy | C10: XL | D10: =R10 -> 1 | R10: 1 | S10: =SUMIFS('UK London sales'!D:D, 'UK London sales'!B:B, B10, 'UK London sales'!C:C, C10) -> 0 | T10: =D10-S10 -> 1
A11: 59 | B11: Polo Shirt Black | C11: S | D11: =R11 -> 1 | R11: 1 | S11: =SUMIFS('UK London sales'!D:D, 'UK London sales'!B:B, B11, 'UK London sales'!C:C, C11) -> 0 | T11: =D11-S11 -> 1
A12: 60 | B12: Polo Shirt Black | C12: M | D12: =R12 -> 0 | R12: 0 | S12: =SUMIFS('UK London sales'!D:D, 'UK London sales'!B:B, B12, 'UK London sales'!C:C, C12) -> 0 | T12: =D12-S12 -> 0
A13: 61 | B13: Polo Shirt Black | C13: L | D13: =R13 -> 2 | R13: 2 | S13: =SUMIFS('UK London sales'!D:D, 'UK London sales'!B:B, B13, 'UK London sales'!C:C, C13) -> 0 | T13: =D13-S13 -> 2
A14: 62 | B14: POLO Shirt Black | C14: XL | D14: =R14 -> 1 | R14: 1 | S14: =SUMIFS('UK London sales'!D:D, 'UK London sales'!B:B, B14, 'UK London sales'!C:C, C14) -> 0 | T14: =D14-S14 -> 1
A15: SOCKS ANKLE
B16: POLO Ankle White | C16: M | D16: =R16 -> 2 | R16: 2 | S16: =SUMIFS('UK London sales'!D:D, 'UK London sales'!B:B, B16, 'UK London sales'!C:C, C16) -> 0 | T16: =D16-S16 -> 2
B17: POLO Ankle White | C17: L | D17: =R17 -> 2 | R17: 2 | S17: =SUMIFS('UK London sales'!D:D, 'UK London sales'!B:B, B17, 'UK London sales'!C:C, C17) -> 0 | T17: =D17-S17 -> 2
B18: ADIDAS Ankle White | C18: M | D18: =R18 -> 2 | R18: 2 | S18: =SUMIFS('UK London sales'!D:D, 'UK London sales'!B:B, B18, 'UK London sales'!C:C, C18) -> 0 | T18: =D18-S18 -> 2
B19: ADIDAS Ankle White | C19: L | D19: =R19 -> 2 | R19: 2 | S19: =SUMIFS('UK London sales'!D:D, 'UK London sales'!B:B, B19, 'UK London sales'!C:C, C19) -> 0 | T19: =D19-S19 -> 2
B20: New Balance Ankle White | C20: M | D20: =R20 -> 2 | R20: 2 | S20: =SUMIFS('UK London sales'!D:D, 'UK London sales'!B:B, B20, 'UK London sales'!C:C, C20) -> 0 | T20: =D20-S20 -> 2
B21: New Balance Ankle White | C21: L | D21: =R21 -> 2 | R21: 2 | S21: =SUMIFS('UK London sales'!D:D, 'UK London sales'!B:B, B21, 'UK London sales'!C:C, C21) -> 0 | T21: =D21-S21 -> 2
B22: NIKE Mix | C22: M | D22: =R22 -> 2 | R22: 2 | S22: =SUMIFS('UK London sales'!D:D, 'UK London sales'!B:B, B22, 'UK London sales'!C:C, C22) -> 0 | T22: =D22-S22 -> 2
B23: NIKE Mix | C23: L | D23: =R23 -> 2 | R23: 2 | S23: =SUMIFS('UK London sales'!D:D, 'UK London sales'!B:B, B23, 'UK London sales'!C:C, C23) -> 0 | T23: =D23-S23 -> 2
B24: POLO Ankle Black | C24: M | D24: =R24 -> 4 | R24: 4 | S24: =SUMIFS('UK London sales'!D:D, 'UK London sales'!B:B, B24, 'UK London sales'!C:C, C24) -> 0 | T24: =D24-S24 -> 4
B25: POLO Ankle Black | C25: L | D25: =R25 -> 0 | R25: 0 | S25: =SUMIFS('UK London sales'!D:D, 'UK London sales'!B:B, B25, 'UK London sales'!C:C, C25) -> 0 | T25: =D25-S25 -> 0
B26: NIKE Ankle Black | C26: M | D26: =R26 -> 2 | R26: 2 | S26: =SUMIFS('UK London sales'!D:D, 'UK London sales'!B:B, B26, 'UK London sales'!C:C, C26) -> 0 | T26: =D26-S26 -> 2
B27: NIKE Ankle Black | C27: L | D27: =R27 -> 2 | R27: 2 | S27: =SUMIFS('UK London sales'!D:D, 'UK London sales'!B:B, B27, 'UK London sales'!C:C, C27) -> 0 | T27: =D27-S27 -> 2
... B31: ADIDAS Ankle Black | C31: L | D31: =R31 -> 2 | R31: 2 | S31: =SUMIFS('UK London sales'!D:D, 'UK London sales'!B:B, B31, 'UK London sales'!C:C, C31) -> 0 | T31: =D31-S31 -> 2
A32: SOCKS FULL
B33: NIKE Full White | C33: M | D33: =R33 -> 2 | R33: 2 | S33: =SUMIFS('UK London sales'!D:D, 'UK London sales'!B:B, B33, 'UK London sales'!C:C, C33) -> 0 | T33: =D33-S33 -> 2
B34: NIKE Full White | C34: L | D34: =R34 -> 2 | R34: 2 | S34: =SUMIFS('UK London sales'!D:D, 'UK London sales'!B:B, B34, 'UK London sales'!C:C, C34) -> 0 | T34: =D34-S34 -> 2
B35: POLO Full White | C35: M | D35: =R35 -> 0 | R35: 0 | S35: =SUMIFS('UK London sales'!D:D, 'UK London sales'!B:B, B35, 'UK London sales'!C:C, C35) -> 0 | T35: =D35-S35 -> 0
B36: POLO Full White | C36: L | D36: =R36 -> 4 | R36: 4 | S36: =SUMIFS('UK London sales'!D:D, 'UK London sales'!B:B, B36, 'UK London sales'!C:C, C36) -> 0 | T36: =D36-S36 -> 4
B37: NEW BALANCE WHITE | C37: M | D37: =R37 -> 2 | R37: 2 | S37: =SUMIFS('UK London sales'!D:D, 'UK London sales'!B:B, B37, 'UK London sales'!C:C, C37) -> 0 | T37: =D37-S37 -> 2
B38: NEW BALANCE WHITE | C38: L | D38: =R38 -> 2 | R38: 2 | S38: =SUMIFS('UK London sales'!D:D, 'UK London sales'!B:B, B38, 'UK London sales'!C:C, C38) -> 0 | T38: =D38-S38 -> 2
B39: NIKE Ankle White | C39: M | D39: =R39 -> 2 | R39: 2 | S39: =SUMIFS('UK London sales'!D:D, 'UK London sales'!B:B, B39, 'UK London sales'!C:C, C39) -> 0 | T39: =D39-S39 -> 2
B40: NIKE Ankle White | C40: L | D40: =R40 -> 2 | R40: 2 | S40: =SUMIFS('UK London sales'!D:D, 'UK London sales'!B:B, B40, 'UK London sales'!C:C, C40) -> 0 | T40: =D40-S40 -> 2
B41: NIKE Full Black | C41: M | D41: =R41 -> 2 | R41: 2 | S41: =SUMIFS('UK London sales'!D:D, 'UK London sales'!B:B, B41, 'UK London sales'!C:C, C41) -> 0 | T41: =D41-S41 -> 2
B42: NIKE Full Black | C42: L | D42: =R42 -> 2 | R42: 2 | S42: =SUMIFS('UK London sales'!D:D, 'UK London sales'!B:B, B42, 'UK London sales'!C:C, C42) -> 0 | T42: =D42-S42 -> 2
B43: POLO Full Black | C43: M | D43: =R43 -> 2 | R43: 2 | S43: =SUMIFS('UK London sales'!D:D, 'UK London sales'!B:B, B43, 'UK London sales'!C:C, C43) -> 0 | T43: =D43-S43 -> 2
...

Sheet UK London sales
C1: Waist | D1: Quantity Sold | E1: Name | F1: Account Name | G1: username | H1: sale price | I1: Bump price | J1: refund | K1: payment status | L1: Processed Sales | M1: Received Amount | O1: Total Sales | P1: Total Bump
A2: 13/11 | B2: 501 Light Blue | C2: 34 | D2: 1 | E2: Ammar | G2: Complete | H2: 24.1 | K2: Complete | L2: =IF(K2="Processed", H2, "") | O2: =(SUM(H:H)) -> 38060.61 | P2: =SUM(I:I) -> 55.33
A3: 13/11 | B3: 501 Light Blue | C3: 34 | D3: 1 | E3: Ammar | G3: laurieholdsworth | H3: 23.4 | K3: Complete
A4: 14/11 | B4: 501 Light Blue | C4: 34 | D4: 1 | E4: Ammar | G4: karenderrick | H4: 26.6 | K4: Complete
A5: 14/11 | B5: 501 Navy Blue | C5: 34 | D5: 1 | E5: Ammar | G5: atylor12 | H5: 25 | K5: Complete
A6: 14/11 | B6: 511 Navy Blue | C6: 32 | D6: 1 | E6: Ammar | G6: adyrev2013 | H6: 25 | K6: Complete
A7: 14/11 | B7: 511 Navy Blue | C7: 34 | D7: 1 | E7: Ammar | G7: adyrev2013 | H7: 25 | K7: Complete
A8: 14/11 | B8: 511 Navy Blue | C8: 32 | D8: 1 | E8: Hamza | G8: bev5871 | H8: 25 | K8: In Process
A9: 14/11 | B9: 501 Light Blue | C9: 36 | D9: 1 | E9: Hamza | G9: leshiett | H9: 29 | I9: 1.11 | K9: In Process
A10: 15/11 | B10: 511 Navy Blue | C10: 34 | D10: 1 | E10: Ammar | G10: ahaqq | H10: 25 | K10: Complete
A11: 15/11 | B11: 501 Light Blue | C11: 36 | D11: 1 | E11: Safie | G11: eezie93 | H11: 24 | I11: 1.21
A12: 15/11 | B12: 501 Light Blue | C12: 34 | D12: 1 | E12: Hamza | G12: crangg | H12: 23 | I12: 1.11 | K12: Complete
A13: 15/11 | B13: 501 Light Blue | C13: 36 | D13: 1 | E13: Hamza | G13: jonathasmr97 | H13: 25 | K13: In Process
A14: 15/11 | B14: 511 Navy Blue | C14: 34 | D14: 1 | E14: Ammar | G14: filipx18 | H14: 23 | K14: Complete
A15: 15/11 | B15: 501 Selvedge | C15: 34 | D15: 1 | E15: Ammar | G15: kebbles | H15: 44 | K15: Complete
A16: 15/11 | B16: 501 Selvedge | C16: 34 | D16: 1 | E16: Ammar | G16: austin199191 | H16: 45.5 | K16: Complete
A17: 16/11 | B17: 511 Navy Blue | C17: 36 | D17: 1 | E17: Safie | G17: neilp42 | H17: 27 | K17: Complete
A18: 16/11 | B18: 501 Light Blue | C18: 32 | D18: 1 | E18: Safie | G18: thefarlowe | H18: 27
A19: 16/11 | B19: 501 Light Blue | C19: 34 | D19: 1 | E19: Ammar | G19: pawels66 | H19: 28 | K19: Complete
A20: 16/11 | B20: 501 Light Blue | C20: 34 | D20: 1 | E20: Safie | G20: blue71135 | H20: 22
A21: 16/11 | B21: 501 Light Blue | C21: 34 | D21: 1 | E21: Hamza | G21: jayb2000 | H21: 25 | K21: Complete
A22: 16/11 | B22: 501 Light Blue | C22: 36 | D22: 1 | E22: Hamza | G22: bb866 | H22: 29 | K22: In Process
A23: 16/11 | B23: 501 Light Blue | C23: 34 | D23: 1 | E23: Safie | G23: Kellyjessica1610 | H23: 26
A24: 16/11 | B24: 501 Light Blue | C24: 34 | D24: 1 | E24: Safie | G24: ct-breezy | H24: 26
A25: 16/11 | B25: 511 Navy Blue | C25: 34 | D25: 1 | E25: Ammar | G25: ashmitch90 | H25: 25 | K25: Complete
A26: 16/11 | B26: 511 Navy Blue | C26: 34 | D26: 1 | E26: Ammar | G26: hbbossnan | H26: 25 | K26: Complete
A27: 16/11 | B27: 511 Navy Blue | C27: 34 | D27: 1 | E27: Ammar | G27: alb2468 | H27: 25 | K27: Complete
A28: 16/11 | B28: 511 Navy Blue | C28: 36 | D28: 1 | E28: Ammar | G28: westmolesey1 | H28: 29 | K28: Complete
A29: 16/11 | B29: 501 Light Blue | C29: 34 | D29: 1 | E29: Safie | G29: denisewight | H29: 25
A30: 16/11 | B30: 511 Navy Blue | C30: 34 | D30: 1 | E30: Ammar | G30: shanzaboy1974 | H30: 28 | K30: Complete
A31: 17/11 | B31: 501 Light Blue | C31: 32 | D31: 1 | E31: Hamza | G31: miko564 | H31: 29 | K31: In Process
A32: 17/11 | B32: 501 Light Blue | C32: 34 | D32: 1 | E32: Safie | G32: ashleywild87 | H32: 22
A33: 17/11 | B33: 511 Navy Blue | C33: 36 | D33: 1 | E33: Safie | G33: papillon2365 | H33: 23.4
A34: 17/11 | B34: 511 Navy Blue | C34: 32 | D34: 1 | E34: Hamza | G34: hxdgy23 | H34: 22.75
A35: 17/11 | B35: 501 Navy Blue | C35: 32 | D35: 1 | E35: Hamza | G35: jxsxn3000 | H35: 25
A36: 17/11 | B36: 501 Navy Blue | C36: 36 | D36: 1 | E36: Hamza | G36: philipw31 | H36: 55.1 | K36: Complete
A37: 17/11 | B37: 511 Navy Blue | C37: 36 | D37: 1 | E37: Hamza | G37: philipw31 | H37: 55.1 | K37: Complete
A38: 17/11 | B38: 511 Navy Blue | C38: 34 | D38: 1 | E38: Hamza | G38: rodrigo.barre | H38: 21 | K38: Complete
A39: 17/11 | B39: 511 Navy Blue | C39: 32 | D39: 1 | E39: Ammar | G39: deano8674 | H39: 23 | K39: Complete
A40: 17/11 | B40: 501 Navy Blue | C40: 34 | D40: 1 | E40: Ammar | G40: martinjamesa | H40: 28 | K40: Complete
...

Sheet Accounts Data
B1: Active | C1: Account User | D1: IP Address | E1: Email Address | F1: Email Passward | G1: Vinted Username | H1: Vinted Password | I1: Phone Number | J1: Identity Verifiy(NAME) | K1: Account Number | L1: Demo Account Number | M1: Phone Number
B2: Rest | C2: Ammar | D2: Mobile | E2: ranaammar046@gmail.com | G2: ranaa302 | H2: gmail login | I2: =447478058070 -> 447478058070
A3: lauren | B3: Rest | C3: Ammar | D3: 23.230.139.218:34691 | E3: lgarry491@gmail.com | F3: Lauren@264 | G3: laureng254 | H3: gmail login | I3: =447988520316 -> 447988520316
A4: Rosalind | B4: Rest | C4: Ammar | D4: 104.252.72.128:49126 | E4: rosalindbeaumont1@gmail.com | F4: Rosalind@264 | G4: rosalindb92 | H4: gmail login | I4: 447828704794
A5: RaimaFatima | B5: Rest | C5: Ammar | E5: raimafatima@proton.me | F5: Aqzaqzaa@3321 | G5: raimafitama | I5: 447462229237
A6: Levi Style Store | B6: Rest | C6: Ammar | D6: 92.113.216.23 (Gologin) | E6: ranaammar03088741046@gmail.com | G6: ranar967 | H6: gmail login | I6: 447352767339
A7: AmmarRana | B7: Rest | C7: Ammar | D7: 82.47.6.174 | E7: ukammar01@thesecondchance.co.uk | G7: amm1ar | I7: 447480260601
A8: amm2 | B8: Active | C8: Ammar | D8: 92.113.78.173 | E8: ukammar03@thesecondchance.co.uk | G8: amm2 | I8: 447473963657
A9: 46082 | B9: Blocked | C9: Ammar | D9: 178.92.57.196 | E9: ukammar05@thesecondchance.co.uk | G9: 46082 | I9: Tem
A10: SanaImran | B10: Rest | C10: Ammar | E10: sanaimrans@proton.me | F10: Aqzaqzaa@ | G10: sanaimran | I10: 447480265249
A11: UK 10 | B11: Active | C11: Ammar | D11: 185.100.169.75 | G11: am046ar
A12: Sammy | B12: Active | C12: Ammar
A13: abbash | B13: Blocked | C13: Ammar | E13: abbash419 | G13: abbash | H13: gmail login
A14: Jane | B14: Active | C14: Faizan | D14: 51.146.185.108:41346 | E14: pauljane1198@gmail.com | G14: janep342 | H14: gmail login | I14: 447,09
A15: Olivia | B15: Active | C15: Faizan | D15: 51.146.185.176:49631 | E15: bennetolivia905@gmail.com | G15: oliviab9624 | H15: gmail login | I15: 447,81
A16: Freya | B16: Blocked | C16: Abdullah Khan | D16: 23.26.203.186:34691 | E16: freyarobinson491@outlook.com | G16: freyar491 | H16: Freya@264 | I16: 447,87
A17: Sanu | B17: Active | C17: Faizan | D17: 00.00.5 | E17: summiyahassan021@gmail.com | G17: sanu443 | H17: gmail login | I17: 447848474201 | J17: ipD CALL.com
A18: BlueThreadPro | B18: Blocked | C18: Faizan | D18: 82.41.248.209 | E18: alizymalik085@gmail.com | F18: aass@1122 | G18: bluethreadpro | H18: gmail login
A19: Jeanify | B19: Blocked | C19: Umar | D19: 92.113.205.201 | E19: d7445344@gmail.com | F19: d@isy987 | G19: levisstore1234
A20: Rosie | B20: Blocked | C20: Umar | D20: 193.106.199.30 | E20: r48197133@gmail.com | F20: rosie@1234 | G20: rosie704 | H20: gmail login | I20: 7737144022 | M20: Vyke( Iphone)
A21: Alexandra | B21: Blocked | C21: Abdullah Malik | D21: Nill | E21: Alexandrawhitaker766@gmail.com | F21: Alexandra@264 | G21: Alexandraw244 | H21: gmail login | I21: 7828707785
A22: Hina | B22: Active | C22: Umar | D22: mobile | E22: hshk915@gmail.com | F22: aass1122 | G22: hinas948 | H22: gmail login | I22: 7828726424
A23: Zainab | B23: Active | C23: Umar | D23: mobile | E23: z3854430@gmail.com | F23: ass@1234 | G23: zainab239 | H23: gmail login | I23: 7454757687
A24: Umar | B24: Active | C24: Umar | D24: mobile | E24: kingredeye63@gmail.com | G24: umar968 | H24: gmail login | I24: 7454756691
A25: Mose | B25: Active | C25: Faizan | D25: 82.39.66.224 | E25: faxanshah42@gmail.com | F25: Faizan#008 | G25: moses423 | H25: gmail login | I25: 7348024514
A26: stark | B26: Blocked | C26: Abdullah Malik | D26: 82.39.66.94 45938 | E26: s11810464@gmail.com | F26: Abcd@1234 | G26: stark240 | H26: gmail login | I26: 7348024762
A27: stefen | B27: Blocked | C27: Abdullah Malik | D27: 82.39.69.28 46940 | E27: S60382417@gmail.com | F27: Abcd@1234 | G27: stefen5 | H27: gmail login | I27: 7470184889
A28: antonio | B28: Active | C28: Abdullah Malik | D28: 82.39.68.89 45933 | E28: a03526794@gmail.com | F28: Abcd@1234 | G28: antonio846 | H28: gmail login | I28: 7480261542
A29: winona | B29: Active | C29: Umar | D29: mobile | E29: mi8968363@gmail.com | F29: aass1122 | G29: winona_987 | H29: gmail login | I29: 7348571124
A30: Sama | B30: Active | C30: Faizan | D30: 82.41.248.225:45820 | E30: samanjali9090@proton.me | F30: Faizan#008 | G30: Sama jeans | H30: Faizan#00 | I30: 7446369274
A31: zoee931 | B31: Active | C31: Abdullah Malik | D31: 92.113.205.96 | E31: zoee1861@gmail.com | F31: Abcd@1234 | G31: zoee93 | H31: gmail login | I31: 7462231582
A32: Umaima | B32: Active | C32: Umar | D32: 82.39.66.96 | E32: umer01@thesecondchance.co.uk | G32: umaima_123 | H32: gmail login | I32: 7346086097
A33: Gwen | B33: Active | C33: Umar | D33: 82.39.67.193 | E33: ukumer02@thesecondchance.co.uk | G33: gwen_543 | H33: gmail login | I33: 7346447334
A34: Umar2 | B34: Active | C34: Umar | D34: 92.113.78.33 | E34: ukumer03@thesecondchance.co.uk | G34: umar_3456 | H34: gmail login | I34: 7342797535
A35: Lucy | B35: Active | C35: Umar | D35: 92.113.78.203 | E35: ukumer05@thesecondchance.co.uk | G35: lucy_8980 | H35: gmail login | I35: 7436736691
A36: leocarter | B36: Blocked | C36: Aali | D36: 46.203.167.41 | E36: uksaif02@thesecondchance.co.uk | G36: leocarter65 | H36: leocarter@65 | I36: 7348336083
A37: emilybrooks | B37: Restricted | C37: Aali | D37: 82.41.248.147 | E37: uksaif01@thesecondchance.co.uk | G37: emilybrooks2 | H37: saifullah@2005 | I37: 7882507146
A38: selena | B38: Blocked | C38: Aali | D38: 82.39.67.88 | E38: rabecca03@thesecondchance.co.uk | G38: selena787 | I38: 7787816539
A39: benharrison | B39: Active | C39: Aali | D39: 185.203.136.217 | E39: uksaif3@thesecondchance.co.uk | G39: benharrison43 | H39: saifullah@2026 | I39: 7346907897

Sheet Accounts
A1: Vinted Name | B1: Account Name | C1: Account Number | D1: Demo Account Number | E1: IMPORTANT!
A2: Polly | B2: Hamza Monzo | C2: Ac: 20946673 C: 04-00-05 | D2: Nill
A3: Jane | B3: Abbas Taptap | C3: Ac: 00174781 C: 04-19-19 | D3: Nill
A4: lauren | B4: Saria Monzo | C4: Ac: 38991926 C: 04-00-06 | D4: Nill
A5: Sanu | B5: Sarim Monzo | C5: Ac: 36409799 C: 04-00-06 | D5: Nill
A6: Olivia | B6: Abbas Nsave | C6: Ac: 00879986 C: 04-09-72 | D6: Ac: 39641166 C: 23-08-01 | E6: DON'T WITHDRAW MORE THAN $200
A7: Freya | B7: Abbas Nsave | C7: Ac: 00879986 C: 04-09-72 | D7: Ac: 39641912 C: 23-08-01 | E7: DON'T WITHDRAW MORE THAN $200
A8: Rosalind | B8: Nosheen Nsave | C8: Ac: 00888379 C: 04-09-72 | D8: Ac: 15204491 C: 23-08-01 | E8: DON'T WITHDRAW MORE THAN $200
A9: Rana | B9: Nosheen Nsave | C9: Ac: 00888379 C: 04-09-72 | D9: Ac: 15202201 C: 23-08-01 | E9: DON'T WITHDRAW MORE THAN $200
A10: Alexandra | B10: Ali Nsave | C10: Ac: 00920476 C: 04-09-72 | D10: Nill | E10: DON'T WITHDRAW MORE THAN $200
A11: Rosie | B11: Faizan Nsave | C11: Ac: 00910931 C: 04-09-72 | D11: Ac: 39645240 C: 23-08-01 | E11: DON'T WITHDRAW MORE THAN $200
A12: Hina | B12: Hamza Nsave | C12: Ac: 00904790 C: 04-09-72 | D12: Ac: 15204401 C: 23-08-01 | E12: DON'T WITHDRAW MORE THAN $200
A13: Zainab | B13: Hamza Nsave | C13: Ac: 00904790 C: 04-09-73 | D13: Ac: 37704401 C: 23-08-01 | E13: DON'T WITHDRAW MORE THAN $200
A14: Umar | B14: Faizan Nsave | C14: Ac: 00910931 C: 04-09-72 | D14: Ac: 39645814 C: 23-08-01 | E14: DON'T WITHDRAW MORE THAN $200
A15: Mose | B15: Abbas Ifast | C15: Ac: 00496939 C: 04-00-01
A16: winona | B16: Abbas Ifast | C16: Ac: 00496939 C: 04-00-01
A17: Levi Style Store | B17: Abbas Taptap Personal | C17: Ac: 00766403 C: 04-19-19 | D17: Ac: 39645220 C: 23-08-01
A18: RaimaFatima | B18: Abbas Taptap Personal | C18: Ac: 00766403 C: 04-19-19 | D18: Ac: 39645320 C: 23-08-01
A19: antonio | B19: Abdullah Nsave | C19: Ac: 01016857 C: 04-09-72
A20: zoee931 | B20: Abdullah Nsave | C20: Ac: 01016857 C: 04-09-72
A21: Umaima | B21: Syeda Khola Shah | C21: Ac: 01016540 C: 04-09-72 | D21: Ac: 39642226 C: 23-08-01
A22: Gwen | B22: Syeda Khola Shah | C22: Ac: 01016540 C: 04-09-72 | D22: Ac: 39642227 C: 23-08-01
A23: SanaImran | B23: Summiya Hassan | C23: Ac: 01016535 C: 040972 | D23: Ac: 39642250 C: 23-08-01
A24: AmmarRana | B24: Summiya Hassan | C24: Ac: 01016535 C: 040972 | D24: Ac: 39642150 C: 23-08-01
A25: Sanu | B25: Sarim Monzo | C25: Ac: 36409799 C: 04-00-06
A26: Sama | B26: Nisar Revoult | C26: Ac: 26248354 C: 23-01-63

Sheet Withdrawal
A1: Date | B1: Vinted Name | C1: Amount | D1: Account Number | E1: Account Name | F1: Demo Account | G1: IMPORTANT!
A2: 46174 | B2: Lauren | C2: 210 | D2: {=IF(E2="","",_xlfn.XLOOKUP(E2,Accounts!B:B,Accounts!C:C,""))} -> Ac: 38991926 C: 04-00-06 | E2: {=IF(B2="","",_xlfn.XLOOKUP(B2,Accounts!A:A,Accounts!B:B,""))} -> Saria Monzo | F2: {=IF(E2="","",_xlfn.XLOOKUP(E2,Accounts!B:B,Accounts!D:D,""))} -> Nill | G2: {=IF(B2:B50498="","",IFERROR(VLOOKUP(B2:B50498,Accounts!A:E,5,FALSE),""))}
A3: 46176 | B3: Jane | C3: 203 | D3: {=IF(E3="","",_xlfn.XLOOKUP(E3,Accounts!B:B,Accounts!C:C,""))} -> Ac: 00174781 C: 04-19-19 | E3: {=IF(B3="","",_xlfn.XLOOKUP(B3,Accounts!A:A,Accounts!B:B,""))} -> Abbas Taptap | F3: {=IF(E3="","",_xlfn.XLOOKUP(E3,Accounts!B:B,Accounts!D:D,""))} -> Nill
A4: 46176 | B4: Olivia | C4: 131 | D4: {=IF(E4="","",_xlfn.XLOOKUP(E4,Accounts!B:B,Accounts!C:C,""))} -> Ac: 00879986 C: 04-09-72 | E4: {=IF(B4="","",_xlfn.XLOOKUP(B4,Accounts!A:A,Accounts!B:B,""))} -> Abbas Nsave | F4: {=IF(E4="","",_xlfn.XLOOKUP(E4,Accounts!B:B,Accounts!D:D,""))} -> Ac: 39641166 C: 23-08-01 | G4: DON'T WITHDRAW MORE THAN $200
A5: 46176 | B5: Freya | C5: 86 | D5: {=IF(E5="","",_xlfn.XLOOKUP(E5,Accounts!B:B,Accounts!C:C,""))} -> Ac: 00879986 C: 04-09-72 | E5: {=IF(B5="","",_xlfn.XLOOKUP(B5,Accounts!A:A,Accounts!B:B,""))} -> Abbas Nsave | F5: {=IF(E5="","",_xlfn.XLOOKUP(E5,Accounts!B:B,Accounts!D:D,""))} -> Ac: 39641166 C: 23-08-01 | G5: DON'T WITHDRAW MORE THAN $200
A6: 46176 | B6: sanu | C6: 124 | D6: {=IF(E6="","",_xlfn.XLOOKUP(E6,Accounts!B:B,Accounts!C:C,""))} -> Ac: 36409799 C: 04-00-06 | E6: {=IF(B6="","",_xlfn.XLOOKUP(B6,Accounts!A:A,Accounts!B:B,""))} -> Sarim Monzo | F6: {=IF(E6="","",_xlfn.XLOOKUP(E6,Accounts!B:B,Accounts!D:D,""))} -> Nill
A7: 46186 | B7: Polly | C7: 104.6 | D7: {=IF(E7="","",_xlfn.XLOOKUP(E7,Accounts!B:B,Accounts!C:C,""))} -> Ac: 20946673 C: 04-00-05 | E7: {=IF(B7="","",_xlfn.XLOOKUP(B7,Accounts!A:A,Accounts!B:B,""))} -> Hamza Monzo | F7: {=IF(E7="","",_xlfn.XLOOKUP(E7,Accounts!B:B,Accounts!D:D,""))} -> Nill
A8: 46188 | B8: Rana | C8: 54 | D8: {=IF(E8="","",_xlfn.XLOOKUP(E8,Accounts!B:B,Accounts!C:C,""))} -> Ac: 00888379 C: 04-09-72 | E8: {=IF(B8="","",_xlfn.XLOOKUP(B8,Accounts!A:A,Accounts!B:B,""))} -> Nosheen Nsave | F8: {=IF(E8="","",_xlfn.XLOOKUP(E8,Accounts!B:B,Accounts!D:D,""))} -> Ac: 15204491 C: 23-08-01 | G8: DON'T WITHDRAW MORE THAN $200
A9: 46188 | B9: Rosalind | C9: 22 | D9: {=IF(E9="","",_xlfn.XLOOKUP(E9,Accounts!B:B,Accounts!C:C,""))} -> Ac: 00888379 C: 04-09-72 | E9: {=IF(B9="","",_xlfn.XLOOKUP(B9,Accounts!A:A,Accounts!B:B,""))} -> Nosheen Nsave | F9: {=IF(E9="","",_xlfn.XLOOKUP(E9,Accounts!B:B,Accounts!D:D,""))} -> Ac: 15204491 C: 23-08-01 | G9: DON'T WITHDRAW MORE THAN $200
A10: 46188 | B10: Sanu | C10: 234 | D10: {=IF(E10="","",_xlfn.XLOOKUP(E10,Accounts!B:B,Accounts!C:C,""))} -> Ac: 36409799 C: 04-00-06 | E10: {=IF(B10="","",_xlfn.XLOOKUP(B10,Accounts!A:A,Accounts!B:B,""))} -> Sarim Monzo | F10: {=IF(E10="","",_xlfn.XLOOKUP(E10,Accounts!B:B,Accounts!D:D,""))} -> Nill
A11: 46188 | B11: lauren | C11: 164 | D11: {=IF(E11="","",_xlfn.XLOOKUP(E11,Accounts!B:B,Accounts!C:C,""))} -> Ac: 38991926 C: 04-00-06 | E11: {=IF(B11="","",_xlfn.XLOOKUP(B11,Accounts!A:A,Accounts!B:B,""))} -> Saria Monzo | F11: {=IF(E11="","",_xlfn.XLOOKUP(E11,Accounts!B:B,Accounts!D:D,""))} -> Nill
A12: 46190 | B12: Polly | C12: 25 | D12: {=IF(E12="","",_xlfn.XLOOKUP(E12,Accounts!B:B,Accounts!C:C,""))} -> Ac: 20946673 C: 04-00-05 | E12: {=IF(B12="","",_xlfn.XLOOKUP(B12,Accounts!A:A,Accounts!B:B,""))} -> Hamza Monzo | F12: {=IF(E12="","",_xlfn.XLOOKUP(E12,Accounts!B:B,Accounts!D:D,""))} -> Nill
A13: 46190 | B13: Alexandra | C13: 62.1 | D13: {=IF(E13="","",_xlfn.XLOOKUP(E13,Accounts!B:B,Accounts!C:C,""))} -> Ac: 00920476 C: 04-09-72 | E13: {=IF(B13="","",_xlfn.XLOOKUP(B13,Accounts!A:A,Accounts!B:B,""))} -> Ali Nsave | F13: {=IF(E13="","",_xlfn.XLOOKUP(E13,Accounts!B:B,Accounts!D:D,""))} -> Nill | G13: DON'T WITHDRAW MORE THAN $200
A14: 46190 | B14: Freya | C14: 138.5 | D14: {=IF(E14="","",_xlfn.XLOOKUP(E14,Accounts!B:B,Accounts!C:C,""))} -> Ac: 00879986 C: 04-09-72 | E14: {=IF(B14="","",_xlfn.XLOOKUP(B14,Accounts!A:A,Accounts!B:B,""))} -> Abbas Nsave | F14: {=IF(E14="","",_xlfn.XLOOKUP(E14,Accounts!B:B,Accounts!D:D,""))} -> Ac: 39641166 C: 23-08-01 | G14: DON'T WITHDRAW MORE THAN $200
A15: 46190 | B15: Jane | C15: 175 | D15: {=IF(E15="","",_xlfn.XLOOKUP(E15,Accounts!B:B,Accounts!C:C,""))} -> Ac: 00174781 C: 04-19-19 | E15: {=IF(B15="","",_xlfn.XLOOKUP(B15,Accounts!A:A,Accounts!B:B,""))} -> Abbas Taptap | F15: {=IF(E15="","",_xlfn.XLOOKUP(E15,Accounts!B:B,Accounts!D:D,""))} -> Nill
A16: 46190 | B16: Olivia | C16: 164 | D16: {=IF(E16="","",_xlfn.XLOOKUP(E16,Accounts!B:B,Accounts!C:C,""))} -> Ac: 00879986 C: 04-09-72 | E16: {=IF(B16="","",_xlfn.XLOOKUP(B16,Accounts!A:A,Accounts!B:B,""))} -> Abbas Nsave | F16: {=IF(E16="","",_xlfn.XLOOKUP(E16,Accounts!B:B,Accounts!D:D,""))} -> Ac: 39641166 C: 23-08-01 | G16: DON'T WITHDRAW MORE THAN $200
A17: 46202 | B17: Sanu | C17: 304.47 | D17: {=IF(E17="","",_xlfn.XLOOKUP(E17,Accounts!B:B,Accounts!C:C,""))} -> Ac: 36409799 C: 04-00-06 | E17: {=IF(B17="","",_xlfn.XLOOKUP(B17,Accounts!A:A,Accounts!B:B,""))} -> Sarim Monzo | F17: {=IF(E17="","",_xlfn.XLOOKUP(E17,Accounts!B:B,Accounts!D:D,""))} -> Nill
A18: 46202 | B18: Jane | C18: 238 | D18: {=IF(E18="","",_xlfn.XLOOKUP(E18,Accounts!B:B,Accounts!C:C,""))} -> Ac: 00174781 C: 04-19-19 | E18: {=IF(B18="","",_xlfn.XLOOKUP(B18,Accounts!A:A,Accounts!B:B,""))} -> Abbas Taptap | F18: {=IF(E18="","",_xlfn.XLOOKUP(E18,Accounts!B:B,Accounts!D:D,""))} -> Nill
A19: 46202 | B19: Olivia | C19: 250 | D19: {=IF(E19="","",_xlfn.XLOOKUP(E19,Accounts!B:B,Accounts!C:C,""))} -> Ac: 00879986 C: 04-09-72 | E19: {=IF(B19="","",_xlfn.XLOOKUP(B19,Accounts!A:A,Accounts!B:B,""))} -> Abbas Nsave | F19: {=IF(E19="","",_xlfn.XLOOKUP(E19,Accounts!B:B,Accounts!D:D,""))} -> Ac: 39641166 C: 23-08-01 | G19: DON'T WITHDRAW MORE THAN $200
A20: 46202 | B20: Rosie | C20: 190 | D20: {=IF(E20="","",_xlfn.XLOOKUP(E20,Accounts!B:B,Accounts!C:C,""))} -> Ac: 00910931 C: 04-09-72 | E20: {=IF(B20="","",_xlfn.XLOOKUP(B20,Accounts!A:A,Accounts!B:B,""))} -> Faizan Nsave | F20: {=IF(E20="","",_xlfn.XLOOKUP(E20,Accounts!B:B,Accounts!D:D,""))} -> Ac: 39645240 C: 23-08-01 | G20: DON'T WITHDRAW MORE THAN $200 | H20: 190
A21: 46202 | B21: Freya | C21: 180 | D21: {=IF(E21="","",_xlfn.XLOOKUP(E21,Accounts!B:B,Accounts!C:C,""))} -> Ac: 00879986 C: 04-09-72 | E21: {=IF(B21="","",_xlfn.XLOOKUP(B21,Accounts!A:A,Accounts!B:B,""))} -> Abbas Nsave | F21: {=IF(E21="","",_xlfn.XLOOKUP(E21,Accounts!B:B,Accounts!D:D,""))} -> Ac: 39641166 C: 23-08-01 | G21: DON'T WITHDRAW MORE THAN $200
A22: 46180 | B22: lauren | C22: 251 | D22: {=IF(E22="","",_xlfn.XLOOKUP(E22,Accounts!B:B,Accounts!C:C,""))} -> Ac: 38991926 C: 04-00-06 | E22: {=IF(B22="","",_xlfn.XLOOKUP(B22,Accounts!A:A,Accounts!B:B,""))} -> Saria Monzo | F22: {=IF(E22="","",_xlfn.XLOOKUP(E22,Accounts!B:B,Accounts!D:D,""))} -> Nill
A23: 46180 | B23: Hina | C23: 118.5 | D23: {=IF(E23="","",_xlfn.XLOOKUP(E23,Accounts!B:B,Accounts!C:C,""))} -> Ac: 00904790 C: 04-09-72 | E23: {=IF(B23="","",_xlfn.XLOOKUP(B23,Accounts!A:A,Accounts!B:B,""))} -> Hamza Nsave | F23: {=IF(E23="","",_xlfn.XLOOKUP(E23,Accounts!B:B,Accounts!D:D,""))} -> Ac: 15204401 C: 23-08-01 | G23: DON'T WITHDRAW MORE THAN $200
A24: 46180 | B24: Zainab | C24: 125 | D24: {=IF(E24="","",_xlfn.XLOOKUP(E24,Accounts!B:B,Accounts!C:C,""))} -> Ac: 00904790 C: 04-09-72 | E24: {=IF(B24="","",_xlfn.XLOOKUP(B24,Accounts!A:A,Accounts!B:B,""))} -> Hamza Nsave | F24: {=IF(E24="","",_xlfn.XLOOKUP(E24,Accounts!B:B,Accounts!D:D,""))} -> Ac: 15204401 C: 23-08-01 | G24: DON'T WITHDRAW MORE THAN $200
A25: 46180 | B25: Rosie | C25: 37.5 | D25: {=IF(E25="","",_xlfn.XLOOKUP(E25,Accounts!B:B,Accounts!C:C,""))} -> Ac: 00910931 C: 04-09-72 | E25: {=IF(B25="","",_xlfn.XLOOKUP(B25,Accounts!A:A,Accounts!B:B,""))} -> Faizan Nsave | F25: {=IF(E25="","",_xlfn.XLOOKUP(E25,Accounts!B:B,Accounts!D:D,""))} -> Ac: 39645240 C: 23-08-01 | G25: DON'T WITHDRAW MORE THAN $200
A26: 46180 | B26: Umar | C26: 59.5 | D26: {=IF(E26="","",_xlfn.XLOOKUP(E26,Accounts!B:B,Accounts!C:C,""))} -> Ac: 00910931 C: 04-09-72 | E26: {=IF(B26="","",_xlfn.XLOOKUP(B26,Accounts!A:A,Accounts!B:B,""))} -> Faizan Nsave | F26: {=IF(E26="","",_xlfn.XLOOKUP(E26,Accounts!B:B,Accounts!D:D,""))} -> Ac: 39645240 C: 23-08-01 | G26: DON'T WITHDRAW MORE THAN $200
A27: 46180 | B27: Rana | C27: 64.22 | D27: {=IF(E27="","",_xlfn.XLOOKUP(E27,Accounts!B:B,Accounts!C:C,""))} -> Ac: 00888379 C: 04-09-72 | E27: {=IF(B27="","",_xlfn.XLOOKUP(B27,Accounts!A:A,Accounts!B:B,""))} -> Nosheen Nsave | F27: {=IF(E27="","",_xlfn.XLOOKUP(E27,Accounts!B:B,Accounts!D:D,""))} -> Ac: 15204491 C: 23-08-01 | G27: DON'T WITHDRAW MORE THAN $200
A28: 46217 | B28: Olivia | C28: 58.65 | D28: {=IF(E28="","",_xlfn.XLOOKUP(E28,Accounts!B:B,Accounts!C:C,""))} -> Ac: 00879986 C: 04-09-72 | E28: {=IF(B28="","",_xlfn.XLOOKUP(B28,Accounts!A:A,Accounts!B:B,""))} -> Abbas Nsave | F28: {=IF(E28="","",_xlfn.XLOOKUP(E28,Accounts!B:B,Accounts!D:D,""))} -> Ac: 39641166 C: 23-08-01 | G28: DON'T WITHDRAW MORE THAN $200
